Workbook

Sheet Assumptions
A1: Nusa AI — Financial Model: Assumptions (все жёлтые ячейки редактируемые)
A3: PRICING (USD/mo, привязано к Rupiah ориентировочно)
A4: Free tier — token allowance/mo | B4: 150 | C4: токены
A5: Tier Basic — price | B5: 3.5 | C5: USD/mo (~Rp 55,000)
A6: Tier Basic — token allowance/mo | B6: 1000 | C6: токены
A7: Tier Pro — price | B7: 9 | C7: USD/mo (~Rp 145,000)
A8: Tier Pro — token allowance/mo | B8: 3500 | C8: токены
A9: Tier Business — price | B9: 24 | C9: USD/mo (~Rp 385,000)
A10: Tier Business — token allowance/mo | B10: 12000 | C10: токены
A11: Top-up pack price (extra 1000 tokens) | B11: 3 | C11: USD
A13: USER MIX / CONVERSION
A14: % free users who convert to any paid tier /mo | B14: 0.04 | C14: доля
A15: Paid mix — % on Basic | B15: 0.55 | C15: доля от платящих
A16: Paid mix — % on Pro | B16: 0.35 | C16: доля от платящих
A17: Paid mix — % on Business | B17: 0.1 | C17: доля от платящих
A18: Monthly churn — paid users | B18: 0.09 | C18: доля/мес
A19: Avg top-up purchases per paying user/mo | B19: 0.3 | C19: шт
A21: COGS — стоимость генерации (USD), см. Этап 04/05
A22: Avg cost per image generation (blended) | B22: 0.012 | C22: USD, см. 04.2 (Runware/DeepInfra/Imagen blend)
A23: Avg cost per video generation (5s, blended) | B23: 0.35 | C23: USD, см. 04.3 (Wan/Kling/Veo blend)
A24: Avg cost per chat message (LLM, blended) | B24: 0.0025 | C24: USD, см. 04.1 (Haiku/Flash-Lite blend)
A25: Avg cost per audio/voice generation | B25: 0.02 | C25: USD, см. 04.4 (ElevenLabs/Groq blend)
A26: Tokens charged per image generation | B26: 8 | C26: токены — продуктовое решение, не факт SYNTX
A27: Tokens charged per video generation (5s) | B27: 120 | C27: токены
A28: Tokens charged per chat message | B28: 1 | C28: токены
A29: Tokens charged per audio generation | B29: 15 | C29: токены
A30: Generation mix — % of TOKENS spent on image | B30: 0.55 | C30: доля токен-трат
A31: Generation mix — % of TOKENS spent on video | B31: 0.15 | C31: доля токен-трат
A32: Generation mix — % of TOKENS spent on chat | B32: 0.25 | C32: доля токен-трат
A33: Generation mix — % of TOKENS spent on audio | B33: 0.05 | C33: доля токен-трат
... A35: Payment processing fee (Midtrans/Xendit avg) | B35: 0.029 | C35: доля от revenue
A37: CAC / MARKETING
A38: Blended CAC per new registered user | B38: 0.9 | C38: USD (Telegram Ads, influencers, ASO)
A39: Blended CAC per new PAYING user | B39: 14 | C39: USD
A40: Organic/referral share of new users | B40: 0.35 | C40: доля, снижает blended CAC
A42: OPEX — фиксированные ежемесячные расходы (USD)
A43: Team cost (S1: 1 AI-first разработчик + fractional legal/design) | B43: 5500 | C43: USD/мес — $220/день x 20 дней (см. 08) + ~$1,100 на подрядчиков
A44: Infra fixed (hosting, DB, CDN, monitoring, GPU reserved) | B44: 900 | C44: USD/мес при <10k users
A45: Infra fixed scaling step (+ per 10k users) | B45: 350 | C45: USD/мес добавка на каждые 10k MAU
A46: Content moderation / compliance tooling | B46: 300 | C46: USD/мес
...

Sheet Unit Economics
A1: Unit Economics (расчёт по формулам из Assumptions)
A3: Blended ARPU (paying user, /mo) | B3: =(Assumptions!$B$5*Assumptions!$B$15+Assumptions!$B$7*Assumptions!$B$16+Assumptions!$B$9*Assumptions!$B$17)+(Assumptions!$B$11*Assumptions!$B$19)
A4: Avg token allowance (weighted by tier mix, /mo) | B4: =(Assumptions!$B$6*Assumptions!$B$15+Assumptions!$B$8*Assumptions!$B$16+Assumptions!$B$10*Assumptions!$B$17)
A5: Tokens actually consumed /mo (allowance x breakage/utilization) | B5: =B4*Assumptions!$B$34
A6: Blended $/token cost (derived from per-generation-type cost & tokens/gen, weighted by token-spend mix) | B6: =(Assumptions!$B$22/Assumptions!$B$26)*Assumptions!$B$30+(Assumptions!$B$23/Assumptions!$B$27)*Assumptions!$B$31+(Assumptions!$B$24/Assumptions!$B$28)*Assumptions!$B$32+(Assumptions!$B$25/Assumptions!$B$29)*Assumptions!$B$33
A7: Blended COGS per paying user (/mo) = tokens consumed x $/token + payment fee | B7: =B5*B6+B3*Assumptions!$B$35
A8: Gross margin per paying user (USD/mo) | B8: =B3-B7
A9: Gross margin % | B9: =B8/B3
A10: Monthly churn (paid) | B10: =Assumptions!$B$18
A11: Customer lifetime (months) | B11: =1/B10
A12: LTV (gross-margin based) | B12: =B8*B11
A13: CAC per paying user (blended incl. organic) | B13: =Assumptions!$B$39*(1-Assumptions!$B$40)
A14: LTV / CAC | B14: =B12/B13
A15: Payback period (months) | B15: =B13/B8
A17: Примечание: ARPU/COGS считаются по paying-пользователю. Free-пользователи учтены в Scenarios через conversion rate. Tokens/generation — продуктовое допущение (не факт SYNTX, см. Этап 06), выбрано так, чтобы блендед $/token был внутренне согласован со стоимостями из Этапа 04.

Sheet Scenarios
A1: Scenarios by MAU (Monthly Active Users) — все метрики считаются формулами
A3: Метрика | B3: 100 MAU | C3: 500 MAU | D3: 1,000 MAU | E3: 5,000 MAU | F3: 10,000 MAU | G3: 50,000 MAU | H3: 100,000 MAU
A4: MAU | B4: 100 | C4: 500 | D4: 1000 | E4: 5000 | F4: 10000 | G4: 50000 | H4: 100000
A5: Paying users (= MAU * conversion) | B5: =B4*Assumptions!$B$14 | C5: =C4*Assumptions!$B$14 | D5: =D4*Assumptions!$B$14 | E5: =E4*Assumptions!$B$14 | F5: =F4*Assumptions!$B$14 | G5: =G4*Assumptions!$B$14 | H5: =H4*Assumptions!$B$14
A6: MRR (USD) | B6: =B5*'Unit Economics'!$B$3 | C6: =C5*'Unit Economics'!$B$3 | D6: =D5*'Unit Economics'!$B$3 | E6: =E5*'Unit Economics'!$B$3 | F6: =F5*'Unit Economics'!$B$3 | G6: =G5*'Unit Economics'!$B$3 | H6: =H5*'Unit Economics'!$B$3
A7: ARR (USD) | B7: =B6*12 | C7: =C6*12 | D7: =D6*12 | E7: =E6*12 | F7: =F6*12 | G7: =G6*12 | H7: =H6*12
A8: COGS total (USD/mo) | B8: =B5*'Unit Economics'!$B$7 | C8: =C5*'Unit Economics'!$B$7 | D8: =D5*'Unit Economics'!$B$7 | E8: =E5*'Unit Economics'!$B$7 | F8: =F5*'Unit Economics'!$B$7 | G8: =G5*'Unit Economics'!$B$7 | H8: =H5*'Unit Economics'!$B$7
A9: Gross profit (USD/mo) | B9: =B6-B8 | C9: =C6-C8 | D9: =D6-D8 | E9: =E6-E8 | F9: =F6-F8 | G9: =G6-G8 | H9: =H6-H8
A10: Gross margin % | B10: =B9/B6 | C10: =C9/C6 | D10: =D9/D6 | E10: =E9/E6 | F10: =F9/F6 | G10: =G9/G6 | H10: =H9/H6
A11: Opex fixed (USD/mo) | B11: =Assumptions!$B$43+Assumptions!$B$44+Assumptions!$B$45*(B4/10000)+Assumptions!$B$46+Assumptions!$B$47 | C11: =Assumptions!$B$43+Assumptions!$B$44+Assumptions!$B$45*(C4/10000)+Assumptions!$B$46+Assumptions!$B$47 | D11: =Assumptions!$B$43+Assumptions!$B$44+Assumptions!$B$45*(D4/10000)+Assumptions!$B$46+Assumptions!$B$47 | E11: =Assumptions!$B$43+Assumptions!$B$44+Assumptions!$B$45*(E4/10000)+Assumptions!$B$46+Assumptions!$B$47 | F11: =Assumptions!$B$43+Assumptions!$B$44+Assumptions!$B$45*(F4/10000)+Assumptions!$B$46+Assumptions!$B$47 | G11: =Assumptions!$B$43+Assumptions!$B$44+Assumptions!$B$45*(G4/10000)+Assumptions!$B$46+Assumptions!$B$47 | H11: =Assumptions!$B$43+Assumptions!$B$44+Assumptions!$B$45*(H4/10000)+Assumptions!$B$46+Assumptions!$B$47
A12: EBITDA (USD/mo) | B12: =B9-B11 | C12: =C9-C11 | D12: =D9-D11 | E12: =E9-E11 | F12: =F9-F11 | G12: =G9-G11 | H12: =H9-H11
A13: EBITDA margin % | B13: =B12/B6 | C13: =C12/C6 | D13: =D12/D6 | E13: =E12/E6 | F13: =F12/F6 | G13: =G12/G6 | H13: =H12/H6
A14: Burn rate (USD/mo, if EBITDA<0) | B14: =IF(B12<0,-B12,0) | C14: =IF(C12<0,-C12,0) | D14: =IF(D12<0,-D12,0) | E14: =IF(E12<0,-E12,0) | F14: =IF(F12<0,-F12,0) | G14: =IF(G12<0,-G12,0) | H14: =IF(H12<0,-H12,0)
A15: CAC spend needed for new payers this mo (USD, assume 15% of payers are net-new/mo) | B15: =B5*0.15*'Unit Economics'!$B$13 | C15: =C5*0.15*'Unit Economics'!$B$13 | D15: =D5*0.15*'Unit Economics'!$B$13 | E15: =E5*0.15*'Unit Economics'!$B$13 | F15: =F5*0.15*'Unit Economics'!$B$13 | G15: =G5*0.15*'Unit Economics'!$B$13 | H15: =H5*0.15*'Unit Economics'!$B$13
A16: LTV (USD) | B16: ='Unit Economics'!$B$12 | C16: ='Unit Economics'!$B$12 | D16: ='Unit Economics'!$B$12 | E16: ='Unit Economics'!$B$12 | F16: ='Unit Economics'!$B$12 | G16: ='Unit Economics'!$B$12 | H16: ='Unit Economics'!$B$12
A17: LTV/CAC | B17: ='Unit Economics'!$B$14 | C17: ='Unit Economics'!$B$14 | D17: ='Unit Economics'!$B$14 | E17: ='Unit Economics'!$B$14 | F17: ='Unit Economics'!$B$14 | G17: ='Unit Economics'!$B$14 | H17: ='Unit Economics'!$B$14
A18: Payback (months) | B18: ='Unit Economics'!$B$15 | C18: ='Unit Economics'!$B$15 | D18: ='Unit Economics'!$B$15 | E18: ='Unit Economics'!$B$15 | F18: ='Unit Economics'!$B$15 | G18: ='Unit Economics'!$B$15 | H18: ='Unit Economics'!$B$15
A19: Break-even MAU (paying-equivalent, static at this Opex level) | B19: =B11/'Unit Economics'!$B$8 | C19: =C11/'Unit Economics'!$B$8 | D19: =D11/'Unit Economics'!$B$8 | E19: =E11/'Unit Economics'!$B$8 | F19: =F11/'Unit Economics'!$B$8 | G19: =G11/'Unit Economics'!$B$8 | H19: =H11/'Unit Economics'!$B$8
A21: Break-even MAU здесь — это платящие пользователи, нужные чтобы Gross Profit = Opex ПРИ Opex ЭТОГО столбца (Opex растёт со шкалой инфры/команды, поэтому это не единая точка, а per-scenario ориентир; см. лист 'Break-Even' для динамической кривой).

Sheet Break-Even
A1: Точка безубыточности — статическая модель (Opex зафиксирован на уровне MVP-команды S2)
A3: Fixed Opex (MVP baseline, USD/mo) | B3: =Assumptions!$B$43+Assumptions!$B$44+Assumptions!$B$46+Assumptions!$B$47
A4: Gross margin per paying user (USD/mo) | B4: ='Unit Economics'!$B$8
A5: Break-even paying users | B5: =B3/B4
A6: Break-even MAU (при текущем conversion rate) | B6: =B5/Assumptions!$B$14

Sheet Cash Flow 24mo
A1: Помесячный Cash Flow — 24 месяца (рост MAU задаётся кривой ниже, редактируемо)
A3: Starting cash (seed) | B3: =Assumptions!$B$50
A5: Месяц | B5: 1 | C5: 2 | D5: 3 | E5: 4 | F5: 5 | G5: 6 | H5: 7 | I5: 8 | J5: 9 | K5: 10 | L5: 11 | M5: 12 | N5: 13 | O5: 14 | P5: 15 | Q5: 16 | R5: 17 | S5: 18 | T5: 19 | U5: 20 | V5: 21 | W5: 22 | X5: 23 | Y5: 24
A6: MAU (input — редактируемо) | B6: 100 | C6: 250 | D6: 500 | E6: 800 | F6: 1200 | G6: 1800 | H6: 2600 | I6: 3600 | J6: 5000 | K6: 6500 | L6: 8200 | M6: 10000 | N6: 13000 | O6: 16500 | P6: 20500 | Q6: 25000 | R6: 30500 | S6: 36500 | T6: 43000 | U6: 50000 | V6: 58000 | W6: 67000 | X6: 78000 | Y6: 100000
A7: Paying users | B7: =B6*Assumptions!$B$14 | C7: =C6*Assumptions!$B$14 | D7: =D6*Assumptions!$B$14 | E7: =E6*Assumptions!$B$14 | F7: =F6*Assumptions!$B$14 | G7: =G6*Assumptions!$B$14 | H7: =H6*Assumptions!$B$14 | I7: =I6*Assumptions!$B$14 | ... Y7: =Y6*Assumptions!$B$14
A8: MRR | B8: =B7*'Unit Economics'!$B$3 | C8: =C7*'Unit Economics'!$B$3 | D8: =D7*'Unit Economics'!$B$3 | E8: =E7*'Unit Economics'!$B$3 | F8: =F7*'Unit Economics'!$B$3 | G8: =G7*'Unit Economics'!$B$3 | H8: =H7*'Unit Economics'!$B$3 | I8: =I7*'Unit Economics'!$B$3 | ... Y8: =Y7*'Unit Economics'!$B$3
A9: COGS | B9: =B7*'Unit Economics'!$B$7 | C9: =C7*'Unit Economics'!$B$7 | D9: =D7*'Unit Economics'!$B$7 | E9: =E7*'Unit Economics'!$B$7 | F9: =F7*'Unit Economics'!$B$7 | G9: =G7*'Unit Economics'!$B$7 | H9: =H7*'Unit Economics'!$B$7 | I9: =I7*'Unit Economics'!$B$7 | ... Y9: =Y7*'Unit Economics'!$B$7
A10: Gross Profit | B10: =B8-B9 | C10: =C8-C9 | D10: =D8-D9 | E10: =E8-E9 | F10: =F8-F9 | G10: =G8-G9 | H10: =H8-H9 | I10: =I8-I9 | ... Y10: =Y8-Y9
A11: Opex | B11: =Assumptions!$B$43+Assumptions!$B$44+Assumptions!$B$45*(B6/10000)+Assumptions!$B$46+Assumptions!$B$47 | C11: =Assumptions!$B$43+Assumptions!$B$44+Assumptions!$B$45*(C6/10000)+Assumptions!$B$46+Assumptions!$B$47 | D11: =Assumptions!$B$43+Assumptions!$B$44+Assumptions!$B$45*(D6/10000)+Assumptions!$B$46+Assumptions!$B$47 | E11: =Assumptions!$B$43+Assumptions!$B$44+Assumptions!$B$45*(E6/10000)+Assumptions!$B$46+Assumptions!$B$47 | F11: =Assumptions!$B$43+Assumptions!$B$44+Assumptions!$B$45*(F6/10000)+Assumptions!$B$46+Assumptions!$B$47 | G11: =Assumptions!$B$43+Assumptions!$B$44+Assumptions!$B$45*(G6/10000)+Assumptions!$B$46+Assumptions!$B$47 | H11: =Assumptions!$B$43+Assumptions!$B$44+Assumptions!$B$45*(H6/10000)+Assumptions!$B$46+Assumptions!$B$47 | I11: =Assumptions!$B$43+Assumptions!$B$44+Assumptions!$B$45*(I6/10000)+Assumptions!$B$46+Assumptions!$B$47 | ... Y11: =Assumptions!$B$43+Assumptions!$B$44+Assumptions!$B$45*(Y6/10000)+Assumptions!$B$46+Assumptions!$B$47
A12: EBITDA | B12: =B10-B11 | C12: =C10-C11 | D12: =D10-D11 | E12: =E10-E11 | F12: =F10-F11 | G12: =G10-G11 | H12: =H10-H11 | I12: =I10-I11 | ... Y12: =Y10-Y11
A13: Cumulative Cash | B13: =B3+B12 | C13: =B13+C12 | D13: =C13+D12 | E13: =D13+E12 | F13: =E13+F12 | G13: =F13+G12 | H13: =G13+H12 | I13: =H13+I12 | J13: =I13+J12 | ... Y13: =X13+Y12
A15: MAU-кривая — иллюстративный сценарий S-curve до 100k MAU за 24 мес.; каждая жёлтая ячейка редактируема для стресс-теста.
